<?xml version='1.0'?>
<sdf version="1.6">
  <model name="car">
    <pose>0 0 1 0 0 0</pose>
    <static>false</static>

    <link name="main">
      
      <pose>0 0 0 0 0 0</pose>
      
      <inertial>
        <mass>1.0</mass>
        <inertia>
          <ixx>0.03</ixx>
          <ixy>0.0</ixy>
          <ixz>0.0</ixz>
          <iyy>0.03</iyy>
          <iyz>0.0</iyz>
          <izz>0.03</izz>
        </inertia>
      </inertial>

      <collision name="collision">
        <geometry>
          <box>
            <size>1 1 1</size>
          </box>
        </geometry>
      </collision>
      
      <visual name="visual">
        
        <geometry>
          <box>
            <size>1 1 1</size>
          </box>
        </geometry>
        
        <material>
          <ambient>0.2 0 0 1</ambient>
        </material>
      </visual>
    
    </link>
    
    <link name="front">
      
      <pose>0.75 0 -0.25 0 0 0</pose>
      
      <inertial>
        <mass>.25</mass>
        <inertia>
          <ixx>0.015</ixx>
          <ixy>0.0</ixy>
          <ixz>0.0</ixz>
          <iyy>0.015</iyy>
          <iyz>0.0</iyz>
          <izz>0.015</izz>
        </inertia>
      </inertial>

      <collision name="collision">
        <geometry>
          <box>
            <size>0.5 1 0.5</size>
          </box>
        </geometry>
      </collision>
      
      <visual name="visual">
        
        <geometry>
          <box>
            <size>0.5 1 0.5</size>
          </box>
        </geometry>
        
        <material>
          <ambient>0.2 0 0 1</ambient>
        </material>
      </visual>
    
    </link>
    
    <link name="frwheel">
      
      <pose>0.75 -0.575 -0.5 -1.570791 0 0</pose>
      
      <inertial>
        <mass>.2</mass>
        <inertia>
          <ixx>0.01</ixx>
          <ixy>0.0</ixy>
          <ixz>0.0</ixz>
          <iyy>0.01</iyy>
          <iyz>0.0</iyz>
          <izz>0.01</izz>
        </inertia>
      </inertial>

      <collision name="collision">
        <geometry>
          <cylinder>
            <radius>0.25</radius>
            <length>0.15</length>
          </cylinder>
        </geometry>
      </collision>
      
      <visual name="visual">
        
        <geometry>
          <cylinder>
            <radius>0.25</radius>
            <length>0.15</length>
          </cylinder>
        </geometry>
        
        <material>
          <ambient>0 0 0.2 1</ambient>
        </material>
      </visual>
    
    </link>
    
    <link name="brwheel">
      
      <pose>-0.25 -0.575 -0.5 -1.570791 0 0</pose>
      
      <inertial>
        <mass>.2</mass>
        <inertia>
          <ixx>0.01</ixx>
          <ixy>0.0</ixy>
          <ixz>0.0</ixz>
          <iyy>0.01</iyy>
          <iyz>0.0</iyz>
          <izz>0.01</izz>
        </inertia>
      </inertial>

      <collision name="collision">
        <geometry>
          <cylinder>
            <radius>0.25</radius>
            <length>0.15</length>
          </cylinder>
        </geometry>
      </collision>
      
      <visual name="visual">
        
        <geometry>
          <cylinder>
            <radius>0.25</radius>
            <length>0.15</length>
          </cylinder>
        </geometry>
        
        <material>
          <ambient>0 0 0.2 1</ambient>
        </material>
      </visual>
    
    </link>
    
    <link name="flwheel">
      
      <pose>0.75 0.575 -0.5 1.570791 0 0</pose>
      
      <inertial>
        <mass>.2</mass>
        <inertia>
          <ixx>0.01</ixx>
          <ixy>0.0</ixy>
          <ixz>0.0</ixz>
          <iyy>0.01</iyy>
          <iyz>0.0</iyz>
          <izz>0.01</izz>
        </inertia>
      </inertial>

      <collision name="collision">
        <geometry>
          <cylinder>
            <radius>0.25</radius>
            <length>0.15</length>
          </cylinder>
        </geometry>
      </collision>
      
      <visual name="visual">
        
        <geometry>
          <cylinder>
            <radius>0.25</radius>
            <length>0.15</length>
          </cylinder>
        </geometry>
        
        <material>
          <ambient>0 0 0.2 1</ambient>
        </material>
      </visual>
    
    </link>
    
    <link name="blwheel">
      
      <pose>-0.25 0.575 -0.5 1.570791 0 0</pose>
      
      <inertial>
        <mass>.2</mass>
        <inertia>
          <ixx>0.01</ixx>
          <ixy>0.0</ixy>
          <ixz>0.0</ixz>
          <iyy>0.01</iyy>
          <iyz>0.0</iyz>
          <izz>0.01</izz>
        </inertia>
      </inertial>

      <collision name="collision">
        <geometry>
          <cylinder>
            <radius>0.25</radius>
            <length>0.15</length>
          </cylinder>
        </geometry>
      </collision>
      
      <visual name="visual">
        
        <geometry>
          <cylinder>
            <radius>0.25</radius>
            <length>0.15</length>
          </cylinder>
        </geometry>
        
        <material>
          <ambient>0 0 0.2 1</ambient>
        </material>
      </visual>
    
    </link>
    
    <joint name="joint_2_boxes" type="fixed">
      <parent>main</parent>
      <child>front</child>
    </joint>
    
    
    <joint name="joint_frwheel" type="revolute">
      <pose>0 0 0.075 0 0 0</pose>
      <parent>front</parent>
      <child>frwheel</child>
      <axis>
        <xyz>0 0 1</xyz>
      </axis>
    </joint>
    
    <joint name="joint_flwheel" type="revolute">
      <pose>0 0 0.075 0 0 0</pose>
      <parent>front</parent>
      <child>flwheel</child>
      <axis>
        <xyz>0 0 1</xyz>
      </axis>
    </joint>
    
    
    <joint name="joint_brwheel" type="revolute">
      <pose>0 0 0.075 0 0 0</pose>
      <parent>main</parent>
      <child>brwheel</child>
      <axis>
        <xyz>0 0 1</xyz>
      </axis>
    </joint>
    
    <joint name="joint_blwheel" type="revolute">
      <pose>0 0 0.075 0 0 0</pose>
      <parent>main</parent>
      <child>blwheel</child>
      <axis>
        <xyz>0 0 1</xyz>
      </axis>
    </joint>

    <plugin name="car_control" filename="libcar_control_plugin.so"/>

  </model>
</sdf>
